Workbook

Sheet 海快錯單統計
G1: 尋找GB326 輸入-海關通關號碼+主提單號 產出-尋找進口日期 YYYY/MM/DD | Q1: 未計算 | R1: 要刪除 | AG1: 因B6F(已收單) 未計算
A2: 客戶 | B2: 船班 | C2: 主提單號 | D2: 船掛 | E2: 清關業者 | F2: 分艙單傳輸日 | G2: 艙單到港日 | H2: 報單傳輸狀態 | J2: 最後傳輸日 | K2: 短到日期 | L2: 是否開立短到單 | M2: 短到票數 | N2: 溢卸票數 | O2: 異常比例 | P2: 接收日期 | Q2: B6F(已收單) | R2: B6A | S2: B6B | T2: B6D | U2: B6E | V2: B6F(未收單) | W2: A03 | Y2: 身分證錯誤 | Z2: 在裝貨港前兩碼為CN、HK、MO時，須填列中文姓名 | AA2: 身分證錯誤+在裝貨港前兩碼為CN、HK、MO時，須填列中文姓名 (ZZZ) | AB2: 其他錯單 | AC2: 無法傳輸總票數 | AD2: 無法傳輸總票數-ZZZ | AE2: 傳輸總票數 | AF2: 錯單比例(實際) | AG2: 錯單比例(含B6F收單)
A3: 捷利 | B3: XIAN XIN | C3: IPC250624600EX | D3: 14PAAF | E3: TPCT(捷豐) | F3: 06/24 | G3: 45833 | H3: V | J3: 45839 | P3: 06/24 | Q3: 0 | R3: 0 | S3: 0 | T3: 1 | U3: 0 | V3: 57 | W3: 0 | Y3: 0 | Z3: 0 | AA3: 0 | AB3: 0 | AC3: =SUM(S3:U3,V3:AB3) -> 58 | AD3: =AC3-AA3 -> 58 | AE3: 581 | AF3: =AC3/AE3 -> 0.099827883 | AG3: =SUM(Q3:AB3)/AE3 -> 0.099827883
A4: 捷利 | B4: XIAN XIN | C4: IPC250624601EX | D4: 14PAAF | E4: TPCT(捷豐) | F4: 06/24 | G4: 45833 | H4: V | J4: 45839 | P4: 06/24 | Q4: 0 | R4: 0 | S4: 0 | T4: 0 | U4: 0 | V4: 35 | W4: 0 | Y4: 0 | Z4: 0 | AA4: 0 | AB4: 0 | AC4: =SUM(S4:U4,V4:AB4) -> 35 | AD4: =AC4-AA4 -> 35 | AE4: 349 | AF4: =AC4/AE4 -> 0.10028653 | AG4: =SUM(Q4:AB4)/AE4 -> 0.10028653
A5: 捷利 | B5: XIAN XIN | C5: IPC250624602EX | D5: 14PAAF | E5: TPCT(捷豐) | F5: 06/24 | G5: 45833 | H5: V | J5: 45839 | P5: 06/24 | Q5: 0 | R5: 0 | S5: 0 | T5: 0 | U5: 0 | V5: 36 | W5: 0 | Y5: 0 | Z5: 0 | AA5: 0 | AB5: 0 | AC5: =SUM(S5:U5,V5:AB5) -> 36 | AD5: =AC5-AA5 -> 36 | AE5: 445 | AF5: =AC5/AE5 -> 0.080898876 | AG5: =SUM(Q5:AB5)/AE5 -> 0.080898876
A6: 捷利 | B6: XIAN XIN | C6: IPC250624603EX | D6: 14PAAF | E6: TPCT(捷豐) | F6: 06/24 | G6: 45833 | H6: V | J6: 45839 | P6: 06/24 | Q6: 0 | R6: 0 | S6: 0 | T6: 0 | U6: 0 | V6: 110 | W6: 0 | Y6: 0 | Z6: 0 | AA6: 0 | AB6: 0 | AC6: =SUM(S6:U6,V6:AB6) -> 110 | AD6: =AC6-AA6 -> 110 | AE6: 636 | AF6: =AC6/AE6 -> 0.17295597 | AG6: =SUM(Q6:AB6)/AE6 -> 0.17295597
A7: 捷利 | B7: XIAN XIN | C7: IPC250624604EX | D7: 14PAAF | E7: TPCT(捷豐) | F7: 06/24 | G7: 45833 | H7: V | J7: 45839 | P7: 06/24 | Q7: 0 | R7: 0 | S7: 0 | T7: 0 | U7: 0 | V7: 81 | W7: 0 | Y7: 0 | Z7: 0 | AA7: 0 | AB7: 0 | AC7: =SUM(S7:U7,V7:AB7) -> 81 | AD7: =AC7-AA7 -> 81 | AE7: 401 | AF7: =AC7/AE7 -> 0.20199501 | AG7: =SUM(Q7:AB7)/AE7 -> 0.20199501
A8: 菜鳥網絡(自營海絲達) | B8: JIN XIN | C8: IPC250624701EX | D8: 14PAAH | E8: 高雄郵聯(捷豐) | F8: 06/24 | G8: 45833 | H8: V | J8: 45838 | P8: 06/24 | Q8: 0 | R8: 0 | S8: 0 | T8: 23 | U8: 28 | V8: 288 | W8: 2 | Y8: 4 | Z8: 2 | AA8: 6 | AB8: 0 | AC8: =SUM(S8:U8,V8:AB8) -> 353 | AD8: =AC8-AA8 -> 347 | AE8: 3436 | AF8: =AC8/AE8 -> 0.10273574 | AG8: =SUM(Q8:AB8)/AE8 -> 0.10273574
C9: IPC250624701EX | D9: 14PAAH | E9: 高雄郵聯(捷豐) | F9: 06/24 | H9: V | P9: 06/24 | Q9: 0 | R9: 0 | S9: 0 | T9: 0 | U9: 0 | V9: 0 | W9: 0 | Y9: 0 | Z9: 0 | AA9: 0 | AB9: 0 | AC9: =SUM(S9:U9,V9:AB9) -> 0 | AD9: =AC9-AA9 -> 0 | AE9: 3436 | AF9: =AC9/AE9 -> 0 | AG9: =SUM(Q9:AB9)/AE9 -> 0 | AH9: 因有扣留多產生出的
A10: 菜鳥網絡(自營海絲達) | B10: XIAN XIN | C10: IPC250624702EX | D10: 14PAAF | E10: TPCT(捷豐) | F10: 06/24 | G10: 45833 | H10: V | J10: 45839 | P10: 06/24 | Q10: 0 | R10: 0 | S10: 0 | T10: 0 | U10: 1 | V10: 161 | W10: 1 | Y10: 0 | Z10: 2 | AA10: 2 | AB10: 0 | AC10: =SUM(S10:U10,V10:AB10) -> 167 | AD10: =AC10-AA10 -> 165 | AE10: 1479 | AF10: =AC10/AE10 -> 0.11291413 | AG10: =SUM(Q10:AB10)/AE10 -> 0.11291413
A11: 菜鳥網絡(自營海絲達) | B11: XIAN XIN | C11: IPC250624703EX | D11: 14PAAF | E11: TPCT(捷豐) | F11: 06/24 | G11: 45833 | H11: V | J11: 45839 | P11: 06/24 | Q11: 0 | R11: 0 | S11: 0 | T11: 0 | U11: 1 | V11: 260 | W11: 1 | Y11: 0 | Z11: 4 | AA11: 4 | AB11: 0 | AC11: =SUM(S11:U11,V11:AB11) -> 270 | AD11: =AC11-AA11 -> 266 | AE11: 1830 | AF11: =AC11/AE11 -> 0.14754098 | AG11: =SUM(Q11:AB11)/AE11 -> 0.14754098
C12: IPC250624703EX | D12: 14PAAF | E12: TPCT(捷豐) | F12: 06/24 | H12: V | P12: 06/24 | Q12: 0 | R12: 0 | S12: 0 | T12: 0 | U12: 0 | V12: 0 | W12: 0 | Y12: 0 | Z12: 0 | AA12: 0 | AB12: 0 | AC12: =SUM(S12:U12,V12:AB12) -> 0 | AD12: =AC12-AA12 -> 0 | AE12: 1830 | AF12: =AC12/AE12 -> 0 | AG12: =SUM(Q12:AB12)/AE12 -> 0 | AH12: 因有扣留多產生出的
A13: 菜鳥網絡(自營海絲達) | B13: JIN XIN | C13: IPC250624704EX | D13: 14PAAH | E13: 高雄郵聯(全旺) | F13: 06/24 | G13: 45833 | H13: V | J13: 45838 | P13: 06/24 | Q13: 0 | R13: 0 | S13: 0 | T13: 14 | U13: 4 | V13: 158 | W13: 3 | Y13: 0 | Z13: 1 | AA13: 1 | AB13: 0 | AC13: =SUM(S13:U13,V13:AB13) -> 181 | AD13: =AC13-AA13 -> 180 | AE13: 1538 | AF13: =AC13/AE13 -> 0.11768531 | AG13: =SUM(Q13:AB13)/AE13 -> 0.11768531
A14: 菜鳥網絡(自營海絲達) | B14: JIN XIN | C14: IPC250624705EX | D14: 14PAAH | E14: 高雄郵聯(全旺) | F14: 06/24 | G14: 45833 | H14: V | J14: 45838 | P14: 06/24 | Q14: 0 | R14: 0 | S14: 0 | T14: 21 | U14: 9 | V14: 199 | W14: 0 | Y14: 3 | Z14: 2 | AA14: 5 | AB14: 0 | AC14: =SUM(S14:U14,V14:AB14) -> 239 | AD14: =AC14-AA14 -> 234 | AE14: 1817 | AF14: =AC14/AE14 -> 0.1315355 | AG14: =SUM(Q14:AB14)/AE14 -> 0.1315355
A15: 菜鳥網絡(自營海絲達) | B15: JIN XIN | C15: IPC250624706EX | D15: 14PAAH | E15: 高雄郵聯(全旺) | F15: 06/24 | G15: 45833 | H15: V | J15: 45838 | P15: 06/24 | Q15: 0 | R15: 0 | S15: 0 | T15: 9 | U15: 4 | V15: 154 | W15: 2 | Y15: 0 | Z15: 0 | AA15: 0 | AB15: 0 | AC15: =SUM(S15:U15,V15:AB15) -> 169 | AD15: =AC15-AA15 -> 169 | AE15: 1276 | AF15: =AC15/AE15 -> 0.13244514 | AG15: =SUM(Q15:AB15)/AE15 -> 0.13244514
A16: 菜鳥網絡(自營海絲達) | B16: JIN XIN | C16: IPC250624707EX | D16: 14PAAH | E16: 高雄郵聯(全旺) | F16: 06/24 | G16: 45833 | H16: V | J16: 45838 | P16: 06/24 | Q16: 0 | R16: 0 | S16: 0 | T16: 8 | U16: 8 | V16: 168 | W16: 2 | Y16: 0 | Z16: 3 | AA16: 3 | AB16: 0 | AC16: =SUM(S16:U16,V16:AB16) -> 192 | AD16: =AC16-AA16 -> 189 | AE16: 1527 | AF16: =AC16/AE16 -> 0.12573674 | AG16: =SUM(Q16:AB16)/AE16 -> 0.12573674
A17: 菜鳥網絡(自營海絲達) | B17: JIN XIN | C17: IPC25062470EX | D17: 14PAAH | E17: 高雄郵聯(全旺) | F17: 06/24 | G17: 45833 | H17: V | J17: 45838 | P17: 06/24 | Q17: 0 | R17: 0 | S17: 0 | T17: 5 | U17: 7 | V17: 166 | W17: 0 | Y17: 1 | Z17: 3 | AA17: 4 | AB17: 0 | AC17: =SUM(S17:U17,V17:AB17) -> 186 | AD17: =AC17-AA17 -> 182 | AE17: 1272 | AF17: =AC17/AE17 -> 0.14622642 | AG17: =SUM(Q17:AB17)/AE17 -> 0.14622642
A18: 菜鳥網絡(自營海絲達) | B18: JIN XIN | C18: IPC250624806EX | D18: 14PAAH | E18: 高雄郵聯(全旺) | F18: 06/24 | G18: 45833 | H18: V | J18: 45838 | P18: 06/24 | Q18: 0 | R18: 0 | S18: 0 | T18: 4 | U18: 4 | V18: 111 | W18: 0 | Y18: 0 | Z18: 1 | AA18: 1 | AB18: 0 | AC18: =SUM(S18:U18,V18:AB18) -> 121 | AD18: =AC18-AA18 -> 120 | AE18: 581 | AF18: =AC18/AE18 -> 0.20826162 | AG18: =SUM(Q18:AB18)/AE18 -> 0.20826162
AC23: 有多N檔
A24: 客戶 | B24: 船班 | C24: 主提單號 | D24: 船掛 | E24: 清關業者 | F24: 分艙單傳輸日 | G24: 到港日 | H24: 報單傳輸狀態 | I24: 參考日期 | J24: 最後傳輸日 | K24: 短到日期 | L24: 是否開立短到單 | M24: 短到票數 | N24: 溢卸票數 | O24: 異常比例 | P24: 接收日期 | Q24: B6F(已收單) | R24: B6A | S24: B6B | T24: B6D | U24: B6E | V24: B6F(未收單) | W24: A03 | X24: N檔 | AA24: ZZZ | AB24: 其他 | AC24: 無法傳輸總票數 | AD24: 無法傳輸總票數-N | AE24: 傳輸總票數 | AF24: 錯單比例(實際) | AG24: 錯單比例(含B6F收單)
A25: 捷利 | B25: XIAN XIN | C25: IPC250624600EX | D25: 14PAAF | E25: TPCT(捷豐) | F25: 45832 | G25: 45833 | H25: V | I25: 45832 | J25: 45839 | O25: =(M25+N25)/AE25 -> 0 | P25: 45832 | Q25: 311 | R25: 0 | S25: 0 | T25: 1 | U25: 0 | V25: 57 | W25: 0 | X25: 0 | AA25: 0 | AB25: 0 | AC25: 58 | AD25: =AC25-X25 -> 58 | AE25: 581 | AF25: 0.099827883 | AG25: 0.63511188
A26: 捷利 | B26: XIAN XIN | C26: IPC250624601EX | D26: 14PAAF | E26: TPCT(捷豐) | F26: 45832 | G26: 45833 | H26: V | I26: 45832 | J26: 45839 | O26: =(M26+N26)/AE26 -> 0 | P26: 45832 | Q26: 169 | R26: 0 | S26: 0 | T26: 0 | U26: 0 | V26: 35 | W26: 0 | X26: 0 | AA26: 0 | AB26: 0 | AC26: 35 | AD26: =AC26-X26 -> 35 | AE26: 349 | AF26: 0.10028653 | AG26: 0.58452722
A27: 捷利 | B27: XIAN XIN | C27: IPC250624602EX | D27: 14PAAF | E27: TPCT(捷豐) | F27: 45832 | G27: 45833 | H27: V | I27: 45832 | J27: 45839 | O27: =(M27+N27)/AE27 -> 0 | P27: 45832 | Q27: 218 | R27: 1 | S27: 0 | T27: 0 | U27: 0 | V27: 36 | W27: 0 | X27: 0 | AA27: 0 | AB27: 0 | AC27: 36 | AD27: =AC27-X27 -> 36 | AE27: 445 | AF27: 0.080898876 | AG27: 0.57078652
A28: 捷利 | B28: XIAN XIN | C28: IPC250624603EX | D28: 14PAAF | E28: TPCT(捷豐) | F28: 45832 | G28: 45833 | H28: V | I28: 45832 | J28: 45839 | O28: =(M28+N28)/AE28 -> 0 | P28: 45832 | Q28: 315 | R28: 0 | S28: 0 | T28: 0 | U28: 0 | V28: 110 | W28: 0 | X28: 0 | AA28: 0 | AB28: 0 | AC28: 110 | AD28: =AC28-X28 -> 110 | AE28: 636 | AF28: 0.17295597 | AG28: 0.66823899
A29: 捷利 | B29: XIAN XIN | C29: IPC250624604EX | D29: 14PAAF | E29: TPCT(捷豐) | F29: 45832 | G29: 45833 | H29: V | I29: 45832 | J29: 45839 | O29: =(M29+N29)/AE29 -> 0 | P29: 45832 | Q29: 166 | R29: 0 | S29: 0 | T29: 0 | U29: 0 | V29: 81 | W29: 0 | X29: 0 | AA29: 0 | AB29: 0 | AC29: 81 | AD29: =AC29-X29 -> 81 | AE29: 401 | AF29: 0.20199501 | AG29: 0.6159601
A30: 菜鳥網絡(自營海絲達) | B30: JIN XIN | C30: IPC250624701EX | D30: 14PAAH | E30: 高雄郵聯(捷豐) | F30: 45832 | G30: 45833 | H30: V | I30: 45832 | J30: 45838 | O30: =(M30+N30)/AE30 -> 0 | P30: 45832 | Q30: 1882 | R30: 23 | S30: 0 | T30: 23 | U30: 28 | V30: 288 | W30: 2 | X30: 0 | AA30: 6 | AB30: 0 | AC30: 347 | AD30: =AC30-X30 -> 347 | AE30: 3436 | AF30: 0.10098952 | AG30: 0.64871944
A31: 菜鳥網絡(自營海絲達) | B31: XIAN XIN | C31: IPC250624702EX | D31: 14PAAF | E31: TPCT(捷豐) | F31: 45832 | G31: 45833 | H31: V | I31: 45832 | J31: 45839 | O31: =(M31+N31)/AE31 -> 0 | P31: 45832 | Q31: 733 | R31: 0 | S31: 0 | T31: 0 | U31: 1 | V31: 161 | W31: 1 | X31: 58 | AA31: 2 | AB31: 0 | AC31: 223 | AD31: =AC31-X31 -> 165 | AE31: 1479 | AF31: 0.15077755 | AG31: 0.64638269
A32: 菜鳥網絡(自營海絲達) | B32: XIAN XIN | C32: IPC250624703EX | D32: 14PAAF | E32: TPCT(捷豐) | F32: 45832 | G32: 45833 | H32: V | I32: 45832 | J32: 45839 | O32: =(M32+N32)/AE32 -> 0 | P32: 45832 | Q32: 875 | R32: 0 | S32: 0 | T32: 0 | U32: 1 | V32: 260 | W32: 1 | X32: 69 | AA32: 4 | AB32: 0 | AC32: 335 | AD32: =AC32-X32 -> 266 | AE32: 1830 | AF32: 0.18306011 | AG32: 0.66120219
A33: 菜鳥網絡(自營海絲達) | B33: JIN XIN | C33: IPC250624704EX | D33: 14PAAH | E33: 高雄郵聯(全旺) | F33: 45832 | G33: 45833 | H33: V | I33: 45832 | J33: 45838 | O33: =(M33+N33)/AE33 -> 0 | P33: 45832 | Q33: 790 | R33: 7 | S33: 0 | T33: 14 | U33: 4 | V33: 158 | W33: 3 | X33: 0 | AA33: 1 | AB33: 0 | AC33: 180 | AD33: =AC33-X33 -> 180 | AE33: 1538 | AF33: 0.11703511 | AG33: 0.63068921
A34: 菜鳥網絡(自營海絲達) | B34: JIN XIN | C34: IPC250624705EX | D34: 14PAAH | E34: 高雄郵聯(全旺) | F34: 45832 | G34: 45833 | H34: V | I34: 45832 | J34: 45838 | O34: =(M34+N34)/AE34 -> 0 | P34: 45832 | Q34: 917 | R34: 5 | S34: 0 | T34: 21 | U34: 9 | V34: 199 | W34: 0 | X34: 0 | AA34: 5 | AB34: 0 | AC34: 234 | AD34: =AC34-X34 -> 234 | AE34: 1817 | AF34: 0.12878371 | AG34: 0.63346175
A35: 菜鳥網絡(自營海絲達) | B35: JIN XIN | C35: IPC250624706EX | D35: 14PAAH | E35: 高雄郵聯(全旺) | F35: 45832 | G35: 45833 | H35: V | I35: 45832 | J35: 45838 | O35: =(M35+N35)/AE35 -> 0 | P35: 45832 | Q35: 652 | R35: 2 | S35: 0 | T35: 9 | U35: 4 | V35: 154 | W35: 2 | X35: 0 | AA35: 0 | AB35: 0 | AC35: 169 | AD35: =AC35-X35 -> 169 | AE35: 1276 | AF35: 0.13244514 | AG35: 0.64341693
A36: 菜鳥網絡(自營海絲達) | B36: JIN XIN | C36: IPC250624707EX | D36: 14PAAH | E36: 高雄郵聯(全旺) | F36: 45832 | G36: 45833 | H36: V | I36: 45832 | J36: 45838 | O36: =(M36+N36)/AE36 -> 0 | P36: 45832 | Q36: 815 | R36: 11 | S36: 0 | T36: 8 | U36: 8 | V36: 168 | W36: 2 | X36: 0 | AA36: 3 | AB36: 0 | AC36: 189 | AD36: =AC36-X36 -> 189 | AE36: 1527 | AF36: 0.1237721 | AG36: 0.65749836
... A38: 菜鳥網絡(自營海絲達) | B38: JIN XIN | C38: IPC250624806EX | D38: 14PAAH | E38: 高雄郵聯(全旺) | F38: 45832 | G38: 45833 | H38: V | I38: 45832 | J38: 45838 | O38: =(M38+N38)/AE38 -> 0 | P38: 45832 | Q38: 264 | R38: 4 | S38: 0 | T38: 4 | U38: 4 | V38: 111 | W38: 0 | X38: 0 | AA38: 1 | AB38: 0 | AC38: 120 | AD38: =AC38-X38 -> 120 | AE38: 581 | AF38: 0.20654045 | AG38: 0.66092943

Sheet 海快錯單明細
A1: 航班主號 | B1: 分提單號碼 | C1: 客戶 | D1: 倉儲 | E1: 到港日 | F1: 主號拆櫃日 | G1: 最後傳輸日 | H1: 現場有貨日期 | I1: 錯誤原因代碼(最新) | J1: 錯誤原因說明(依新-->舊) | K1: 錯單次數 | L1: 進口人英文名稱 | M1: 進口人統一編號 | N1: 進口人電話 | O1: 毛重 | P1: 件數 | Q1: 貨物名稱 | R1: 單價金額 | S1: 發票總金額 | T1: 進口人英文地址 | U1: 派件公司 | V1: 配送單號 | W1: LP NO | X1: 是否需更新預委 | Y1: 客服提供日期 | Z1: 正確ID | AA1: 正確姓名 | AB1: 正確進口人電話 | AC1: 正確品名 | AD1: 正確金額 | AE1: 今天客服狀態 | AF1: 累積處置說明
A2: IPC250624600EX | B2: 0H4FYW0QEV | C2: 捷利 | D2: TPCT(捷豐) | E2: 06/25 | G2: 45840 | I2: B6F | J2: 2025-06-24 17:49:02，B6F | K2: 1 | L2: 黃遠麗 | M2: F228492291 | N2: TEL0903599928 | O2: 29.100 | P2: 1 | Q2: 展示架 | R2: 1422.00 | S2: 1422.000 | T2: 桃園市平鎮區華隆街16巷18號 | U2: 捷豐新竹 | V2: 1124918723
A3: IPC250624600EX | B3: 0H4FYWTG59 | C3: 捷利 | D3: TPCT(捷豐) | E3: 06/25 | G3: 45840 | I3: B6F | J3: 2025-06-24 17:48:52，B6F | K3: 1 | L3: 林友豪 | M3: F127965533 | N3: TEL0955902102 | O3: 1.100 | P3: 1 | Q3: Stage peripheral equipment | R3: 486.00 | S3: 486.000 | T3: 基隆市七堵區自治街24號1樓 | U3: 捷豐新竹 | V3: 1124923133
A4: IPC250624600EX | B4: 0H4FYWNUC4 | C4: 捷利 | D4: TPCT(捷豐) | E4: 06/25 | G4: 45840 | I4: B6F | J4: 2025-06-24 17:48:59，B6F | K4: 1 | L4: 鄭國彬 | M4: K121702741 | N4: TEL0912962228 | O4: 19.650 | P4: 1 | Q4: 噴壺 | R4: 450.00 | S4: 450.000 | T4: 桃園市大溪鎮介壽路1259巷17弄20號 | U4: HCTA | V4: 1124922805
A5: IPC250624600EX | B5: 0H4FYWS8Z5 | C5: 捷利 | D5: TPCT(捷豐) | E5: 06/25 | G5: 45840 | I5: B6F | J5: 2025-06-24 17:48:50，B6F | K5: 1 | L5: 孫妍庭 | M5: A223735698 | N5: TEL0921135565 | O5: 0.450 | P5: 1 | Q5: 女裝上衣 | R5: 155.00 | S5: 155.000 | T5: 桃園市大園區領航北路4段352-6號4樓 | U5: HCTA | V5: 1124923004
A6: IPC250624600EX | B6: 0H4FYX60WH | C6: 捷利 | D6: TPCT(捷豐) | E6: 06/25 | G6: 45840 | I6: B6F | J6: 2025-06-24 17:48:55，B6F | K6: 1 | L6: 黃盈瑄 | M6: A221667722 | N6: TEL0980779000 | O6: 4.350 | P6: 1 | Q6: catalogue | R6: 162.00 | S6: 162.000 | T6: 新竹市東區高翠路327巷4弄34號 | U6: HCTA | V6: 1124924415
A7: IPC250624600EX | B7: 0H4FYX8WJC | C7: 捷利 | D7: TPCT(捷豐) | E7: 06/25 | G7: 45840 | I7: B6F | J7: 2025-06-24 17:48:38，B6F | K7: 1 | L7: 張力仁 | M7: N121910709 | N7: TEL0985790168 | O7: 4.500 | P7: 1 | Q7: 記號筆 | R7: 31.00 | S7: 31.000 | T7: 臺北市士林區仰德大道3段191-2號1樓 | U7: HCTA | V7: 1124924721
A8: IPC250624600EX | B8: 0H4FYX7TSY | C8: 捷利 | D8: TPCT(捷豐) | E8: 06/25 | G8: 45840 | I8: B6F | J8: 2025-06-24 17:48:37，B6F | K8: 1 | L8: 譚均皓 | M8: A126577847 | N8: TEL0933054946 | O8: 27.000 | P8: 1 | Q8: 吊飾 | R8: 78.61 | S8: 235.830 | T8: 臺北市北投區光明路169巷8號3樓 | U8: 捷豐新竹 | V8: 1124924603
A9: IPC250624600EX | B9: 0H4FYXFN6X | C9: 捷利 | D9: TPCT(捷豐) | E9: 06/25 | G9: 45840 | I9: B6F | J9: 2025-06-24 17:48:57，B6F | K9: 1 | L9: 林玫芸 | M9: B221685310 | N9: TEL0900128777 | O9: 0.600 | P9: 1 | Q9: plastic accessories for plaything | R9: 324.00 | S9: 324.000 | T9: 台中市北屯區歡喜自在社區 | U9: HCTA | V9: 1124925233
A10: IPC250624600EX | B10: 0H4FYXFCYB | C10: 捷利 | D10: TPCT(捷豐) | E10: 06/25 | G10: 45840 | I10: B6F | J10: 2025-06-24 17:48:58，B6F | K10: 1 | L10: 王秋萍 | M10: L222364078 | N10: TEL0981927778 | O10: 2.950 | P10: 4 | Q10: 短褲 | R10: 180.00 | S10: 180.000 | T10: 台中市大肚區沙田路二段721號 | U10: HCTA | V10: 1124930225
A11: IPC250624600EX | B11: 0H4FYXJUJ9 | C11: 捷利 | D11: TPCT(捷豐) | E11: 06/25 | G11: 45840 | I11: B6F | J11: 2025-06-24 17:48:54，B6F | K11: 1 | L11: 蕭春芳 | M11: C220116568 | N11: TEL0910511050 | O11: 3.950 | P11: 1 | Q11: 地墊 | R11: 248.00 | S11: 496.000 | T11: 桃園市龜山區文禾路241號9樓之1 | U11: HCTA | V11: 1124925465
A12: IPC250624600EX | B12: 0H4FYXMTG5 | C12: 捷利 | D12: TPCT(捷豐) | E12: 06/25 | G12: 45840 | I12: B6F | J12: 2025-06-24 17:49:13，B6F | K12: 1 | L12: 鄭怡婷 | M12: H225082428 | N12: TEL0981553506 | O12: 50.000 | P12: 2 | Q12: 傳動配件 | R12: 695.81 | S12: 695.810 | T12: 桃園市中壢市榮民路452號 | U12: 捷豐新竹 | V12: 1124925690
A13: IPC250624600EX | B13: 0H4FYXTB7B | C13: 捷利 | D13: TPCT(捷豐) | E13: 06/25 | G13: 45840 | I13: B6F | J13: 2025-06-24 17:49:58，B6F | K13: 1 | L13: 李有義 | M13: B121112981 | N13: TEL0908691316 | O13: 4.550 | P13: 2 | Q13: 層架 | R13: 184.00 | S13: 184.000 | T13: 台中市北區健行路585號 | U13: HCTA | V13: 1124928851
... A274: IPC250624604EX | B274: 0H4FZ5FMJ8 | C274: 捷利 | D274: TPCT(捷豐) | E274: 06/25 | G274: 45840 | I274: B6F | J274: 2025-06-24 18:24:15，B6F | K274: 1 | L274: 李志吟 | M274: F223741253 | N274: TEL0925356013 | O274: 16.670 | P274: 1 | Q274: Women's cotton clothes | R274: 295.86 | S274: 887.580 | T274: 高雄市高雄市鳳山區海洋一路36號 | U274: HCTA | V274: 1124945194
A275: IPC250624604EX | B275: 0H4FZ5FKU0 | C275: 捷利 | D275: TPCT(捷豐) | E275: 06/25 | G275: 45840 | I275: B6F | J275: 2025-06-24 18:24:05，B6F | K275: 1 | L275: 劉柚岑 | N275: TEL0932260350 | O275: 4.070 | P275: 1 | Q275: 胎壓計 | R275: 338.00 | S275: 338.000 | T275: 高雄市林園區高雄市林園區潭頭裡金潭路279巷23弄11號 | U275: HCTA | V275: 1124945161
A276: IPC250624604EX | B276: 0H4FZ5GA5R | C276: 捷利 | D276: TPCT(捷豐) | E276: 06/25 | G276: 45840 | I276: B6F | J276: 2025-06-24 18:24:23，B6F | K276: 1 | L276: 彭棏隆 | M276: J120536813 | N276: TEL0922392111 | O276: 13.770 | P276: 1 | Q276: 桌布 | R276: 222.46 | S276: 444.920 | T276: 臺北市臺北市內湖區文湖街31號6樓 | U276: HCTA | V276: 1124945264
A277: IPC250624604EX | B277: 0H4FZ5BVGK | C277: 捷利 | D277: TPCT(捷豐) | E277: 06/25 | G277: 45840 | I277: B6F | J277: 2025-06-24 18:24:30，B6F | K277: 1 | L277: 鄭晴方 | M277: J220936020 | N277: TEL0913597363 | O277: 13.520 | P277: 1 | Q277: 風扇及鼓風機之零件 | R277: 92.94 | S277: 743.520 | T277: 臺東縣臺東縣台東市傳廣路155號 | U277: HCTA | V277: 1124944951
A278: IPC250624604EX | B278: 0H4FZ5DGY1 | C278: 捷利 | D278: TPCT(捷豐) | E278: 06/25 | G278: 45840 | I278: B6F | J278: 2025-06-24 18:24:26，B6F | K278: 1 | L278: 邱敬傑 | M278: I100159225 | N278: TEL0909760207 | O278: 23.220 | P278: 1 | Q278: 收納掛袋 | R278: 8.08 | S278: 1212.000 | T278: 嘉義市嘉義市西區北榮街149號送到馨善生活館 | U278: HCTA | V278: 1124945054
A279: IPC250624604EX | B279: 0H4FZ5ECG2 | C279: 捷利 | D279: TPCT(捷豐) | E279: 06/25 | G279: 45840 | I279: B6F | J279: 2025-06-24 18:23:54，B6F | K279: 1 | L279: 王新翔 | M279: P123258981 | N279: TEL0913633325 | O279: 30.650 | P279: 2 | Q279: 光串 | R279: 10.55 | S279: 1266.000 | T279: 彰化縣彰化縣鹿港鎮彰頂路325號 | U279: HCTA | V279: 1124945091
A280: IPC250624604EX | B280: 0H4FZ5G5RY | C280: 捷利 | D280: TPCT(捷豐) | E280: 06/25 | G280: 45840 | I280: B6F | J280: 2025-06-24 18:24:11，B6F | K280: 1 | L280: 張雯婷 | M280: K221938609 | N280: TEL0911666313 | O280: 3.860 | P280: 1 | Q280: 短褲 | R280: 105.27 | S280: 421.080 | T280: 苗栗縣苗栗縣苗栗市中山路736號 | U280: HCTA | V280: 1124945220
A281: IPC250624604EX | B281: 0H4FZ5E80E | C281: 捷利 | D281: TPCT(捷豐) | E281: 06/25 | G281: 45840 | I281: B6F | J281: 2025-06-24 18:24:09，B6F | K281: 1 | L281: 朱皎菁 | M281: E224214843 | N281: TEL0923771002 | O281: 13.450 | P281: 1 | Q281: 套裝 | R281: 267.14 | S281: 267.140 | T281: 高雄市前鎮區西海街28號 | U281: HCTA | V281: 1124945021
A282: IPC250624604EX | B282: 0H4FZ5NWYH | C282: 捷利 | D282: TPCT(捷豐) | E282: 06/25 | G282: 45840 | I282: B6F | J282: 2025-06-24 18:23:51，B6F | K282: 1 | L282: 林欣誼 | M282: G222102762 | N282: TEL0988620690 | O282: 16.000 | P282: 1 | Q282: VEST | R282: 586.66 | S282: 586.660 | T282: 臺北市臺北市信義區吳興街284巷20弄16號2樓 | U282: HCTA | V282: 1124946196
A283: IPC250624604EX | B283: 0H4FZ5QFSA | C283: 捷利 | D283: TPCT(捷豐) | E283: 06/25 | G283: 45840 | I283: B6F | J283: 2025-06-24 18:23:50，B6F | K283: 1 | L283: 劉宛柔 | M283: M222215240 | N283: TEL0926575792 | O283: 2.630 | P283: 1 | Q283: 手袋 | R283: 366.42 | S283: 732.840 | T283: 臺中市臺中市大裏區上興街二段54巷21號 | U283: HCTA | V283: 1124946303
A284: IPC250624604EX | B284: 0H4FZ5R9DP | C284: 捷利 | D284: TPCT(捷豐) | E284: 06/25 | G284: 45840 | I284: B6F | J284: 2025-06-24 18:24:06，B6F | K284: 1 | L284: 林怡珍 | M284: A224531229 | N284: TEL0960056655 | O284: 0.650 | P284: 1 | Q284: 上衣 | R284: 458.64 | S284: 917.280 | T284: 臺北市臺北市大安區忠孝東路四段155號11樓之6 | U284: HCTA | V284: 1124946340
A285: IPC250624604EX | B285: 0H4FZ5SFT3 | C285: 捷利 | D285: TPCT(捷豐) | E285: 06/25 | G285: 45840 | I285: B6F | J285: 2025-06-24 18:24:24，B6F | K285: 1 | L285: 鄭琳盈 | M285: F226161275 | N285: TEL0912207618 | O285: 1.020 | P285: 1 | Q285: 量尺 | R285: 82.45 | S285: 824.500 | T285: 新北市新北市鶯歌區鶯桃路48號 | U285: HCTA | V285: 1124946454
A286: IPC250624604EX | B286: 0H4FZ5WKUC | C286: 捷利 | D286: TPCT(捷豐) | E286: 06/25 | G286: 45840 | I286: B6F | J286: 2025-06-24 18:24:23，B6F | K286: 1 | L286: 陳昌駒 | M286: F130963632 | N286: TEL0970717615 | O286: 12.200 | P286: 1 | Q286: 舞台設備零件 | R286: 501.03 | S286: 1002.060 | T286: 桃園市桃園區國聖一街61號5樓之3 | U286: 捷豐新竹 | V286: 1124947563
A287: IPC250624604EX | B287: 0H4FZ5R1P9 | C287: 捷利 | D287: TPCT(捷豐) | E287: 06/25 | G287: 45840 | I287: B6F | J287: 2025-06-24 18:24:06，B6F | K287: 1 | L287: 趙曼君 | M287: A228579476 | N287: TEL0987380115 | O287: 13.820 | P287: 1 | Q287: 椅子 | R287: 306.00 | S287: 306.000 | T287: 新北市新北市蘆洲區光榮路120巷8弄3號1樓 | U287: HCTA | V287: 1124946336
... A319: IPC250624604EX | B319: 0H4FZBHV19 | C319: 捷利 | D319: TPCT(捷豐) | E319: 06/25 | G319: 45840 | I319: B6F | J319: 2025-06-24 18:24:58，B6F | K319: 1 | L319: 黃苡璇 | M319: J222695504 | N319: TEL0927850121 | O319: 1.950 | P319: 1 | Q319: 拖把 | R319: 262.00 | S319: 262.000 | T319: 新竹市北區新竹市北區成功路192巷328號14樓之二 | U319: 捷豐新竹 | V319: 1124960325
A320: IPC250624701EX | B320: 05715506098 | C320: 菜鳥網絡(自營海絲達) | D320: 高雄郵聯(捷豐) | E320: 06/25 | G320: 45838 | I320: B6F | J320: 2025-06-24 17:19:38，B6F | K320: 1 | L320: 黃奕淳 | M320: P224149910 | N320: TEL0928037671 | O320: 13.570 | P320: 1 | Q320: 配戴飾 | R320: 0.35 | S320: 2875.250 | T320: 臺北市中山區民權東路二段152巷14號 | U320: 菜鳥全家 | V320: 05715506098 | W320: LP00743958409638
A321: IPC250624701EX | B321: 05715506483 | C321: 菜鳥網絡(自營海絲達) | D321: 高雄郵聯(捷豐) | E321: 06/25 | G321: 45838 | I321: B6D | J321: 2025-06-24 17:19:33，B6D | K321: 1 | L321: 陳思辰 | M321: M220754146 | N321: TEL0913300219 | O321: 1.320 | P321: 1 | Q321: 襯衫 | R321: 129.11 | S321: 1032.880 | T321: 新北市三重區三和路三段59號 | U321: 菜鳥全家 | V321: 05715506483 | W321: LP00742991745275
A322: IPC250624604EX | B322: 0H4FZBJQRB | C322: 捷利 | D322: TPCT(捷豐) | E322: 06/25 | G322: 45840 | I322: B6F | J322: 2025-06-24 18:24:51，B6F | K322: 1 | L322: 洪銘賢 | M322: L120392625 | N322: TEL0931191333 | O322: 5.450 | P322: 1 | Q322: 置物箱 | R322: 903.80 | S322: 903.800 | T322: 新北市三峽區介壽路一段276巷106號1樓 | U322: 捷豐新竹 | V322: 1124960340
A323: IPC250624604EX | B323: 0H4FZBZ322 | C323: 捷利 | D323: TPCT(捷豐) | E323: 06/25 | G323: 45840 | I323: B6F | J323: 2025-06-24 18:24:52，B6F | K323: 1 | L323: 陳素真 | M323: S220637734 | N323: TEL0910981270 | O323: 15.950 | P323: 1 | Q323: 收納櫃 | R323: 971.43 | S323: 971.430 | T323: 高雄市大寮區會結裡會興三街350號 | U323: 捷豐新竹 | V323: 1124961051
A324: IPC250624701EX | B324: 05715507098 | C324: 菜鳥網絡(自營海絲達) | D324: 高雄郵聯(捷豐) | E324: 06/25 | G324: 45838 | I324: B6F | J324: 2025-06-24 17:20:02，B6F | K324: 1 | L324: 吳辰宣 | M324: H225463558 | N324: TEL0965633629 | O324: 0.450 | P324: 1 | Q324: 襯衫 | R324: 731.00 | S324: 731.000 | T324: 新北市林口區文化二路一段68巷1號1樓 | U324: 菜鳥全家 | V324: 05715507098 | W324: LP00741973211646
A325: IPC250624701EX | B325: 05715507293 | C325: 菜鳥網絡(自營海絲達) | D325: 高雄郵聯(捷豐) | E325: 06/25 | G325: 45838 | I325: B6E | J325: 2025-06-24 17:19:28，B6E | K325: 1 | L325: 楊朝欽 | M325: L120528134 | N325: TEL0975362389 | O325: 0.120 | P325: 1 | Q325: 釣魚手套 | R325: 249.40 | S325: 249.400 | T325: 台中市大甲區中山路一段1549號 | U325: 菜鳥全家 | V325: 05715507293 | W325: LP00742992074288
A326: IPC250624701EX | B326: 05715507581 | C326: 菜鳥網絡(自營海絲達) | D326: 高雄郵聯(捷豐) | E326: 06/25 | G326: 45838 | I326: B6F | J326: 2025-06-24 17:19:16，B6F | K326: 1 | L326: 廖維後 | M326: H800656791 | N326: TEL0926727143 | O326: 0.500 | P326: 1 | Q326: 牛仔褲 | R326: 211.99 | S326: 211.990 | T326: 桃園市中壢區龍岡路二段313號1樓 | U326: 菜鳥全家 | V326: 05715507581 | W326: LP00742043249424
A327: IPC250624701EX | B327: 05715507378 | C327: 菜鳥網絡(自營海絲達) | D327: 高雄郵聯(捷豐) | E327: 06/25 | G327: 45838 | I327: B6F | J327: 2025-06-24 17:19:30，B6F | K327: 1 | L327: 劉秋妍 | M327: T225999338 | N327: TEL0917578890 | O327: 0.030 | P327: 1 | Q327: 手機鏈 | R327: 122.10 | S327: 122.100 | T327: 高雄市橋頭區糖廠路2-1號一樓 | U327: 菜鳥全家 | V327: 05715507378 | W327: LP00742974975679
A328: IPC250624701EX | B328: 05715507685 | C328: 菜鳥網絡(自營海絲達) | D328: 高雄郵聯(捷豐) | E328: 06/25 | G328: 45838 | I328: B6F | J328: 2025-06-24 17:19:23，B6F | K328: 1 | L328: 胥凱翔 | M328: H125748358 | N328: TEL0900156766 | O328: 0.880 | P328: 1 | Q328: 手機殼 | R328: 824.18 | S328: 824.180 | T328: 桃園市觀音區保障村大觀路一段345號 | U328: 菜鳥全家 | V328: 05715507685 | W328: LP00742973960212
A329: IPC250624701EX | B329: 05715507700 | C329: 菜鳥網絡(自營海絲達) | D329: 高雄郵聯(捷豐) | E329: 06/25 | G329: 45838 | I329: B6F | J329: 2025-06-24 17:19:24，B6F | K329: 1 | L329: 廖雪蓮 | M329: A230652962 | N329: TEL0930675803 | O329: 0.530 | P329: 1 | Q329: 大碼連衣裙 | R329: 147.49 | S329: 294.980 | T329: 新北市中和區新生街8號1樓 | U329: 菜鳥全家 | V329: 05715507700 | W329: LP00742998200656
A330: IPC250624701EX | B330: 05715507785 | C330: 菜鳥網絡(自營海絲達) | D330: 高雄郵聯(捷豐) | E330: 06/25 | G330: 45838 | I330: B6F | J330: 2025-06-24 17:19:24，B6F | K330: 1 | L330: 許盈瑀 | M330: F226892775 | N330: TEL0905691560 | O330: 4.700 | P330: 1 | Q330: 衛褲 | R330: 215.45 | S330: 430.900 | T330: 台中市西區樂群街61之4號 | U330: 菜鳥全家 | V330: 05715507785 | W330: LP00743983027802
A331: IPC250624701EX | B331: 05715508096 | C331: 菜鳥網絡(自營海絲達) | D331: 高雄郵聯(捷豐) | E331: 06/25 | G331: 45838 | I331: B6F | J331: 2025-06-24 17:19:55，B6F | K331: 1 | L331: 李若騏 | M331: E126123281 | N331: TEL0954095670 | O331: 1.450 | P331: 1 | Q331: T恤 | R331: 240.34 | S331: 721.020 | T331: 花蓮縣壽豐鄉志學村中正路17號 | U331: 菜鳥全家 | V331: 05715508096 | W331: LP00742931696155
...

Sheet 未有狀態
A1: 主提單號 | B1: 分提單號 | C1: 是否為後段報關 | F1: 以下這些不應出現此頁 1.扣留件 2.功能【海塊作業】的【海快作業錯單】有上傳的單號
A2: IPC250624603EX | B2: 0H4FZ6XU7D | C2: V
A3: IPC250624604EX | B3: 0H4FZ7WMDT | C3: V
A4: IPC250624604EX | B4: 0H4FZ7V3BG | C4: V
A5: IPC250624604EX | B5: 0H4FZ7TKA3 | C5: V
A6: IPC250624701EX | B6: 7693351713 | F6: 扣留件
A7: IPC250624701EX | B7: 7693350630 | F7: 扣留件
A8: IPC250624701EX | B8: 7693344750 | F8: =VLOOKUP(B8,海快錯單明細!B:I,8,FALSE) -> 在裝貨港前兩碼為CN、HK、MO時，須填列中文姓名
A9: IPC250624701EX | B9: 20898946 | F9: =VLOOKUP(B9,海快錯單明細!B:I,8,FALSE) -> 身分證錯誤請提供正確
A10: IPC250624701EX | B10: 20897437 | F10: =VLOOKUP(B10,海快錯單明細!B:I,8,FALSE) -> 身分證錯誤請提供正確
A11: IPC250624701EX | B11: 05715510851 | F11: =VLOOKUP(B11,海快錯單明細!B:I,8,FALSE) -> 身分證錯誤請提供正確
A12: IPC250624701EX | B12: 05715510055 | F12: =VLOOKUP(B12,海快錯單明細!B:I,8,FALSE) -> 身分證錯誤請提供正確
A13: IPC250624701EX | B13: 05715509953 | F13: =VLOOKUP(B13,海快錯單明細!B:I,8,FALSE) -> 在裝貨港前兩碼為CN、HK、MO時，須填列中文姓名
A14: IPC250624702EX | B14: 7693345306 | F14: =VLOOKUP(B14,海快錯單明細!B:I,8,FALSE) -> 在裝貨港前兩碼為CN、HK、MO時，須填列中文姓名
A15: IPC250624702EX | B15: 7693319701 | F15: =VLOOKUP(B15,海快錯單明細!B:I,8,FALSE) -> 在裝貨港前兩碼為CN、HK、MO時，須填列中文姓名
A16: IPC250624702EX | B16: 7161779052 | C16: V
A17: IPC250624702EX | B17: 7161774082 | C17: V
A18: IPC250624702EX | B18: 7161755650 | C18: V
A19: IPC250624702EX | B19: 7161748742 | C19: V
A20: IPC250624702EX | B20: 7161748731 | C20: V
A21: IPC250624702EX | B21: 7161747832 | C21: V
A22: IPC250624702EX | B22: 7161746863 | C22: V
A23: IPC250624702EX | B23: 7161739900 | C23: V
A24: IPC250624702EX | B24: 7161739863 | C24: V
A25: IPC250624703EX | B25: 7161776252 | C25: V
A26: IPC250624703EX | B26: 7161779203 | C26: V
A27: IPC250624703EX | B27: 7161782202 | C27: V
... A33: IPC250624703EX | B33: 7161773345 | C33: V
A34: IPC250624703EX | B34: 7693432316 | F34: =VLOOKUP(B34,海快錯單明細!B:I,8,FALSE) -> 在裝貨港前兩碼為CN、HK、MO時，須填列中文姓名
A35: IPC250624703EX | B35: 7693415866 | F35: =VLOOKUP(B35,海快錯單明細!B:I,8,FALSE) -> 在裝貨港前兩碼為CN、HK、MO時，須填列中文姓名
A36: IPC250624703EX | B36: 7693464634 | F36: 扣留件
A37: IPC250624703EX | B37: 7693474515 | F37: =VLOOKUP(B37,海快錯單明細!B:I,8,FALSE) -> 在裝貨港前兩碼為CN、HK、MO時，須填列中文姓名
A38: IPC250624703EX | B38: 7693474681 | F38: 扣留件
A39: IPC250624703EX | B39: 7693495051 | F39: =VLOOKUP(B39,海快錯單明細!B:I,8,FALSE) -> 在裝貨港前兩碼為CN、HK、MO時，須填列中文姓名
A40: IPC250624704EX | B40: 7693412926 | F40: =VLOOKUP(B40,海快錯單明細!B:I,8,FALSE) -> 在裝貨港前兩碼為CN、HK、MO時，須填列中文姓名
A41: IPC250624705EX | B41: 7693425832 | F41: =VLOOKUP(B41,海快錯單明細!B:I,8,FALSE) -> 在裝貨港前兩碼為CN、HK、MO時，須填列中文姓名
A42: IPC250624705EX | B42: 7693359940 | F42: =VLOOKUP(B42,海快錯單明細!B:I,8,FALSE) -> 身分證錯誤請提供正確
A43: IPC250624705EX | B43: 7693399851 | F43: =VLOOKUP(B43,海快錯單明細!B:I,8,FALSE) -> 身分證錯誤請提供正確
A44: IPC250624705EX | B44: 7693409732 | F44: =VLOOKUP(B44,海快錯單明細!B:I,8,FALSE) -> 身分證錯誤請提供正確
A45: IPC250624705EX | B45: 7693417292 | F45: =VLOOKUP(B45,海快錯單明細!B:I,8,FALSE) -> 在裝貨港前兩碼為CN、HK、MO時，須填列中文姓名
...
